<?xml version="1.0" encoding="utf-8"?>
<robot name="Armar4">
        <link name="ArmL_Elb1_link">
		<inertial>
			<mass value="0.61"/>
			<origin xyz="-2.55375e-07 -0.0334756 -0.026321" rpy="0 -0 0"/>
			<inertia ixx="0.00114668" ixy="0" ixz="0" iyy="0.000480917" iyz="0" izz="0.0010953"/>
		</inertial>
		<visual>
			<origin xyz="0 0 0" rpy="0 -0 0"/>
			<geometry>
				<mesh filename="stl/ArmL_Elb1_joint_visu.stl" scale="1 1 1"/>
			</geometry>
		</visual>
		<collision>
			<origin xyz="0 0 0" rpy="0 -0 0"/>
			<geometry>
				<mesh filename="stl/ArmL_Elb1_joint_col.stl" scale="1 1 1"/>
			</geometry>
		</collision>
	</link>
        <link name="ArmL_Elb2_link">
		<inertial>
			<mass value="0.43"/>
			<origin xyz="0.00297504 -3.05709e-05 -0.0877993" rpy="0 -0 0"/>
			<inertia ixx="0.00142316" ixy="0" ixz="0" iyy="0.00122507" iyz="0" izz="0.000422436"/>
		</inertial>
		<visual>
			<origin xyz="0 0 0" rpy="0 -0 0"/>
			<geometry>
				<mesh filename="stl/ArmL_Elb2_joint_visu.stl" scale="1 1 1"/>
			</geometry>
		</visual>
		<collision>
			<origin xyz="0 0 0" rpy="0 -0 0"/>
			<geometry>
				<mesh filename="stl/ArmL_Elb2_joint_col.stl" scale="1 1 1"/>
			</geometry>
		</collision>
	</link>
        <link name="ArmL_Sho1_link">
		<inertial>
			<mass value="0.58"/>
			<origin xyz="-0.00635488 0.0837574 -0.0328287" rpy="0 -0 0"/>
			<inertia ixx="0.00137353" ixy="0" ixz="0" iyy="0.00204376" iyz="0" izz="0.00196295"/>
		</inertial>
		<visual>
			<origin xyz="0 0 0" rpy="0 -0 0"/>
			<geometry>
				<mesh filename="stl/ArmL_Sho1_joint_visu.stl" scale="1 1 1"/>
			</geometry>
		</visual>
		<collision>
			<origin xyz="0 0 0" rpy="0 -0 0"/>
			<geometry>
				<mesh filename="stl/ArmL_Sho1_joint_col.stl" scale="1 1 1"/>
			</geometry>
		</collision>
	</link>
        <link name="ArmL_Sho2_link">
		<inertial>
			<mass value="0.52"/>
			<origin xyz="-0.00149987 -0.00344511 -0.0512163" rpy="0 -0 0"/>
			<inertia ixx="0.000596991" ixy="0" ixz="0" iyy="0.000663986" iyz="0" izz="0.000420505"/>
		</inertial>
		<visual>
			<origin xyz="0 0 0" rpy="0 -0 0"/>
			<geometry>
				<mesh filename="stl/ArmL_Sho2_joint_visu.stl" scale="1 1 1"/>
			</geometry>
		</visual>
		<collision>
			<origin xyz="0 0 0" rpy="0 -0 0"/>
			<geometry>
				<mesh filename="stl/ArmL_Sho2_joint_col.stl" scale="1 1 1"/>
			</geometry>
		</collision>
	</link>
        <link name="ArmL_Sho3_link">
		<inertial>
			<mass value="0.51"/>
			<origin xyz="1.66285e-07 -0.0575318 0.0134998" rpy="0 -0 0"/>
			<inertia ixx="0.00109943" ixy="0" ixz="0" iyy="0.000491725" iyz="0" izz="0.00106067"/>
		</inertial>
		<visual>
			<origin xyz="0 0 0" rpy="0 -0 0"/>
			<geometry>
				<mesh filename="stl/ArmL_Sho3_joint_visu.stl" scale="1 1 1"/>
			</geometry>
		</visual>
		<collision>
			<origin xyz="0 0 0" rpy="0 -0 0"/>
			<geometry>
				<mesh filename="stl/ArmL_Sho3_joint_col.stl" scale="1 1 1"/>
			</geometry>
		</collision>
	</link>
        <link name="ArmL_Sho4_link">
		<inertial>
			<mass value="1.44"/>
			<origin xyz="0.00188906 -0.00191048 -0.110437" rpy="0 -0 0"/>
			<inertia ixx="0.00541288" ixy="0" ixz="0" iyy="0.00551224" iyz="0" izz="0.0011448"/>
		</inertial>
		<visual>
			<origin xyz="0 0 0" rpy="0 -0 0"/>
			<geometry>
				<mesh filename="stl/ArmL_Sho4_joint_visu.stl" scale="1 1 1"/>
			</geometry>
		</visual>
		<collision>
			<origin xyz="0 0 0" rpy="0 -0 0"/>
			<geometry>
				<mesh filename="stl/ArmL_Sho4_joint_col.stl" scale="1 1 1"/>
			</geometry>
		</collision>
	</link>
        <link name="ArmL_Wri1_link">
		<inertial>
			<mass value="0.5"/>
			<origin xyz="0 0 -0.000109262" rpy="0 -0 0"/>
			<inertia ixx="3.29711e-05" ixy="0" ixz="0" iyy="3.2789e-05" iyz="0" izz="3.31512e-05"/>
		</inertial>
		<visual>
			<origin xyz="0 0 0" rpy="0 -0 0"/>
			<geometry>
				<mesh filename="stl/ArmL_Wri1_joint_visu.stl" scale="1 1 1"/>
			</geometry>
		</visual>
		<collision>
			<origin xyz="0 0 0" rpy="0 -0 0"/>
			<geometry>
				<mesh filename="stl/sphere10.stl" scale="1 1 1"/>
			</geometry>
		</collision>
	</link>
        <link name="ArmL_Wri2_link">
		<inertial>
			<mass value="0.58"/>
			<origin xyz="0.0306435 -0.00259348 8.21687e-06" rpy="0 -0 0"/>
			<inertia ixx="0.000423639" ixy="0" ixz="0" iyy="0.000982669" iyz="0" izz="0.00079084"/>
		</inertial>
		<visual>
			<origin xyz="0 0 0" rpy="0 -0 0"/>
			<geometry>
				<mesh filename="stl/ArmL_Wri2_joint_visu.stl" scale="1 1 1"/>
			</geometry>
		</visual>
		<collision>
			<origin xyz="0 0 0" rpy="0 -0 0"/>
			<geometry>
				<mesh filename="stl/ArmL_Wri2_joint_col.stl" scale="1 1 1"/>
			</geometry>
		</collision>
	</link>
        <link name="ArmR_Elb1_link">
		<inertial>
			<mass value="0.61"/>
			<origin xyz="-2.35824e-08 -0.0334757 -0.0166789" rpy="0 -0 0"/>
			<inertia ixx="0.00114668" ixy="0" ixz="0" iyy="0.000480918" iyz="0" izz="0.0010953"/>
		</inertial>
		<visual>
			<origin xyz="0 0 0" rpy="0 -0 0"/>
			<geometry>
				<mesh filename="stl/ArmR_Elb1_joint_visu.stl" scale="1 1 1"/>
			</geometry>
		</visual>
		<collision>
			<origin xyz="0 0 0" rpy="0 -0 0"/>
			<geometry>
				<mesh filename="stl/ArmR_Elb1_joint_col.stl" scale="1 1 1"/>
			</geometry>
		</collision>
	</link>
        <link name="ArmR_Elb2_link">
		<inertial>
			<mass value="0.43"/>
			<origin xyz="-0.000975135 3.10054e-05 0.0877994" rpy="0 -0 0"/>
			<inertia ixx="0.00142282" ixy="0" ixz="0" iyy="0.00122507" iyz="0" izz="0.000422095"/>
		</inertial>
		<visual>
			<origin xyz="0 0 0" rpy="0 -0 0"/>
			<geometry>
				<mesh filename="stl/ArmR_Elb2_joint_visu.stl" scale="1 1 1"/>
			</geometry>
		</visual>
		<collision>
			<origin xyz="0 0 0" rpy="0 -0 0"/>
			<geometry>
				<mesh filename="stl/ArmR_Elb2_joint_col.stl" scale="1 1 1"/>
			</geometry>
		</collision>
	</link>
        <link name="ArmR_Sho1_link">
		<inertial>
			<mass value="0.77"/>
			<origin xyz="-0.00635496 0.109694 0.0328288" rpy="0 -0 0"/>
			<inertia ixx="0.00182348" ixy="0" ixz="0" iyy="0.00271326" iyz="0" izz="0.00260599"/>
		</inertial>
		<visual>
			<origin xyz="0 0 0" rpy="0 -0 0"/>
			<geometry>
				<mesh filename="stl/ArmR_Sho1_joint_visu.stl" scale="1 1 1"/>
			</geometry>
		</visual>
		<collision>
			<origin xyz="0 0 0" rpy="0 -0 0"/>
			<geometry>
				<mesh filename="stl/ArmR_Sho1_joint_col.stl" scale="1 1 1"/>
			</geometry>
		</collision>
	</link>
        <link name="ArmR_Sho2_link">
		<inertial>
			<mass value="0.58"/>
			<origin xyz="-0.00150001 -1.73714e-05 0.0492432" rpy="0 -0 0"/>
			<inertia ixx="0.00061498" ixy="0" ixz="0" iyy="0.000689705" iyz="0" izz="0.000469024"/>
		</inertial>
		<visual>
			<origin xyz="0 0 0" rpy="0 -0 0"/>
			<geometry>
				<mesh filename="stl/ArmR_Sho2_joint_visu.stl" scale="1 1 1"/>
			</geometry>
		</visual>
		<collision>
			<origin xyz="0 0 0" rpy="0 -0 0"/>
			<geometry>
				<mesh filename="stl/ArmR_Sho2_joint_col.stl" scale="1 1 1"/>
			</geometry>
		</collision>
	</link>
        <link name="ArmR_Sho3_link">
		<inertial>
			<mass value="0.51"/>
			<origin xyz="7.45773e-08 0.0575321 0.0195" rpy="0 -0 0"/>
			<inertia ixx="0.00109943" ixy="0" ixz="0" iyy="0.000491725" iyz="0" izz="0.00106067"/>
		</inertial>
		<visual>
			<origin xyz="0 0 0" rpy="0 -0 0"/>
			<geometry>
				<mesh filename="stl/ArmR_Sho3_joint_visu.stl" scale="1 1 1"/>
			</geometry>
		</visual>
		<collision>
			<origin xyz="0 0 0" rpy="0 -0 0"/>
			<geometry>
				<mesh filename="stl/ArmR_Sho3_joint_col.stl" scale="1 1 1"/>
			</geometry>
		</collision>
	</link>
        <link name="ArmR_Sho4_link">
		<inertial>
			<mass value="1.44"/>
			<origin xyz="-0.00549999 0.00800005 0.114167" rpy="0 -0 0"/>
			<inertia ixx="0.00678104" ixy="0" ixz="0" iyy="0.00688041" iyz="0" izz="0.0011448"/>
		</inertial>
		<visual>
			<origin xyz="0 0 0" rpy="0 -0 0"/>
			<geometry>
				<mesh filename="stl/ArmR_Sho4_joint_visu.stl" scale="1 1 1"/>
			</geometry>
		</visual>
		<collision>
			<origin xyz="0 0 0" rpy="0 -0 0"/>
			<geometry>
				<mesh filename="stl/ArmR_Sho4_joint_col.stl" scale="1 1 1"/>
			</geometry>
		</collision>
	</link>
        <link name="ArmR_Wri1_link">
		<inertial>
			<mass value="0.5"/>
			<origin xyz="-1.77636e-18 0 -0.000109262" rpy="0 -0 0"/>
			<inertia ixx="3.29711e-05" ixy="0" ixz="0" iyy="3.2789e-05" iyz="0" izz="3.31512e-05"/>
		</inertial>
		<visual>
			<origin xyz="0 0 0" rpy="0 -0 0"/>
			<geometry>
				<mesh filename="stl/ArmR_Wri1_joint_visu.stl" scale="1 1 1"/>
			</geometry>
		</visual>
		<collision>
			<origin xyz="0 0 0" rpy="0 -0 0"/>
			<geometry>
				<mesh filename="stl/sphere10.stl" scale="1 1 1"/>
			</geometry>
		</collision>
	</link>
        <link name="ArmR_Wri2_link">
		<inertial>
			<mass value="0.58"/>
			<origin xyz="0.0306436 -9.36201e-05 -7.88343e-06" rpy="0 -0 0"/>
			<inertia ixx="0.000423253" ixy="0" ixz="0" iyy="0.000982141" iyz="0" izz="0.00079098"/>
		</inertial>
		<visual>
			<origin xyz="0 0 0" rpy="0 -0 0"/>
			<geometry>
				<mesh filename="stl/ArmR_Wri2_joint_visu.stl" scale="1 1 1"/>
			</geometry>
		</visual>
		<collision>
			<origin xyz="0 0 0" rpy="0 -0 0"/>
			<geometry>
				<mesh filename="stl/ArmR_Wri2_joint_col.stl" scale="1 1 1"/>
			</geometry>
		</collision>
	</link>
	<link name="Chest_link">
		<inertial>
			<mass value="0"/>
			<origin xyz="0 0 0" rpy="0 -0 0"/>
			<inertia ixx="1" ixy="0" ixz="0" iyy="1" iyz="0" izz="1"/>
		</inertial>
	</link>
        <link name="EyeL_1_link">
		<inertial>
			<mass value="0.05"/>
			<origin xyz="0.00263 0.0195 0.0209718" rpy="0 -0 0"/>
			<inertia ixx="3.37322e-05" ixy="0" ixz="0" iyy="2.84992e-05" iyz="0" izz="3.21752e-05"/>
		</inertial>
		<visual>
			<origin xyz="0 0 0" rpy="0 -0 0"/>
			<geometry>
				<mesh filename="stl/EyeL_1_joint_visu.stl" scale="1 1 1"/>
			</geometry>
		</visual>
		<collision>
			<origin xyz="0 0 0" rpy="0 -0 0"/>
			<geometry>
				<mesh filename="stl/EyeL_1_joint_visu.stl" scale="1 1 1"/>
			</geometry>
		</collision>
	</link>
        <link name="EyeL_2_link">
		<inertial>
			<mass value="0.05"/>
			<origin xyz="0.00624997 -2.28882e-08 -0.00269467" rpy="0 -0 0"/>
			<inertia ixx="2.18594e-05" ixy="0" ixz="0" iyy="1.52203e-05" iyz="0" izz="1.41891e-05"/>
		</inertial>
		<visual>
			<origin xyz="0 0 0" rpy="0 -0 0"/>
			<geometry>
				<mesh filename="stl/EyeL_2_joint_visu.stl" scale="1 1 1"/>
			</geometry>
		</visual>
		<collision>
			<origin xyz="0 0 0" rpy="0 -0 0"/>
			<geometry>
				<mesh filename="stl/EyeL_2_joint_col.stl" scale="1 1 1"/>
			</geometry>
		</collision>
	</link>
        <link name="EyeR_1_link">
		<inertial>
			<mass value="0.05"/>
			<origin xyz="0.00262998 0.0195 -0.0148501" rpy="0 -0 0"/>
			<inertia ixx="3.53995e-05" ixy="0" ixz="0" iyy="3.01665e-05" iyz="0" izz="3.21752e-05"/>
		</inertial>
		<visual>
			<origin xyz="0 0 0" rpy="0 -0 0"/>
			<geometry>
				<mesh filename="stl/EyeR_1_joint_visu.stl" scale="1 1 1"/>
			</geometry>
		</visual>
		<collision>
			<origin xyz="0 0 0" rpy="0 -0 0"/>
			<geometry>
				<mesh filename="stl/EyeR_1_joint_visu.stl" scale="1 1 1"/>
			</geometry>
		</collision>
	</link>
        <link name="EyeR_2_link">
		<inertial>
			<mass value="0.05"/>
			<origin xyz="0.00624992 1.71661e-08 0.00269455" rpy="0 -0 0"/>
			<inertia ixx="2.18594e-05" ixy="0" ixz="0" iyy="1.52203e-05" iyz="0" izz="1.41891e-05"/>
		</inertial>
		<visual>
			<origin xyz="0 0 0" rpy="0 -0 0"/>
			<geometry>
				<mesh filename="stl/EyeR_2_joint_visu.stl" scale="1 1 1"/>
			</geometry>
		</visual>
		<collision>
			<origin xyz="0 0 0" rpy="0 -0 0"/>
			<geometry>
				<mesh filename="stl/EyeR_2_joint_visu.stl" scale="1 1 1"/>
			</geometry>
		</collision>
	</link>
        <link name="HandL_Finger_Index1_link">
		<inertial>
			<mass value="0.05"/>
			<origin xyz="0.0221634 -0.00896459 0.00233813" rpy="0 -0 0"/>
			<inertia ixx="2.07679e-06" ixy="0" ixz="0" iyy="1.09969e-05" iyz="0" izz="1.18508e-05"/>
		</inertial>
		<visual>
			<origin xyz="0 0 0" rpy="0 -0 0"/>
			<geometry>
				<mesh filename="stl/HandL_Finger_Index1_joint_visu.stl" scale="1 1 1"/>
			</geometry>
		</visual>
		<collision>
			<origin xyz="0 0 0" rpy="0 -0 0"/>
			<geometry>
				<mesh filename="stl/HandL_Finger_Index1_joint_col.stl" scale="1 1 1"/>
			</geometry>
		</collision>
	</link>
        <link name="HandL_Finger_Index2_link">
		<inertial>
			<mass value="0.05"/>
			<origin xyz="0.0126357 -0.00834728 0.00201315" rpy="0 -0 0"/>
			<inertia ixx="2.61714e-06" ixy="0" ixz="0" iyy="1.64377e-05" iyz="0" izz="1.67053e-05"/>
		</inertial>
		<visual>
			<origin xyz="0 0 0" rpy="0 -0 0"/>
			<geometry>
				<mesh filename="stl/HandL_Finger_Index2_joint_visu.stl" scale="1 1 1"/>
			</geometry>
		</visual>
		<collision>
			<origin xyz="0 0 0" rpy="0 -0 0"/>
			<geometry>
				<mesh filename="stl/HandL_Finger_Index2_joint_col.stl" scale="1 1 1"/>
			</geometry>
		</collision>
	</link>
        <link name="HandL_Finger_Middle1_link">
		<inertial>
			<mass value="0.05"/>
			<origin xyz="0.0224319 -0.00941866 0.00186457" rpy="0 -0 0"/>
			<inertia ixx="2.14484e-06" ixy="0" ixz="0" iyy="1.08094e-05" iyz="0" izz="1.17542e-05"/>
		</inertial>
		<visual>
			<origin xyz="0 0 0" rpy="0 -0 0"/>
			<geometry>
				<mesh filename="stl/HandL_Finger_Middle1_joint_visu.stl" scale="1 1 1"/>
			</geometry>
		</visual>
		<collision>
			<origin xyz="0 0 0" rpy="0 -0 0"/>
			<geometry>
				<mesh filename="stl/HandL_Finger_Middle1_joint_col.stl" scale="1 1 1"/>
			</geometry>
		</collision>
	</link>
        <link name="HandL_Finger_Middle2_link">
		<inertial>
			<mass value="0.05"/>
			<origin xyz="0.0127924 -0.009382 0.00184998" rpy="0 -0 0"/>
			<inertia ixx="2.71866e-06" ixy="0" ixz="0" iyy="1.61015e-05" iyz="0" izz="1.64868e-05"/>
		</inertial>
		<visual>
			<origin xyz="0 0 0" rpy="0 -0 0"/>
			<geometry>
				<mesh filename="stl/HandL_Finger_Middle2_joint_visu.stl" scale="1 1 1"/>
			</geometry>
		</visual>
		<collision>
			<origin xyz="0 0 0" rpy="0 -0 0"/>
			<geometry>
				<mesh filename="stl/HandL_Finger_Middle2_joint_col.stl" scale="1 1 1"/>
			</geometry>
		</collision>
	</link>
        <link name="HandL_Finger_Pinky1_link">
		<inertial>
			<mass value="0.05"/>
			<origin xyz="0.0137648 -0.00795003 0.00188619" rpy="0 -0 0"/>
			<inertia ixx="1.7364e-06" ixy="0" ixz="0" iyy="4.73757e-06" iyz="0" izz="5.26992e-06"/>
		</inertial>
		<visual>
			<origin xyz="0 0 0" rpy="0 -0 0"/>
			<geometry>
				<mesh filename="stl/HandL_Finger_Pinky1_joint_visu.stl" scale="1 1 1"/>
			</geometry>
		</visual>
		<collision>
			<origin xyz="0 0 0" rpy="0 -0 0"/>
			<geometry>
				<mesh filename="stl/HandL_Finger_Pinky1_joint_col.stl" scale="1 1 1"/>
			</geometry>
		</collision>
	</link>
        <link name="HandL_Finger_Pinky2_link">
		<inertial>
			<mass value="0.05"/>
			<origin xyz="0.00993043 -0.00882504 0.00149763" rpy="0 -0 0"/>
			<inertia ixx="2.14949e-06" ixy="0" ixz="0" iyy="1.28698e-05" iyz="0" izz="1.34959e-05"/>
		</inertial>
		<visual>
			<origin xyz="0 0 0" rpy="0 -0 0"/>
			<geometry>
				<mesh filename="stl/HandL_Finger_Pinky2_joint_visu.stl" scale="1 1 1"/>
			</geometry>
		</visual>
		<collision>
			<origin xyz="0 0 0" rpy="0 -0 0"/>
			<geometry>
				<mesh filename="stl/HandL_Finger_Pinky2_joint_col.stl" scale="1 1 1"/>
			</geometry>
		</collision>
	</link>
        <link name="HandL_Finger_Ring1_link">
		<inertial>
			<mass value="0.05"/>
			<origin xyz="0.0201865 -0.00755002 0.00209084" rpy="0 -0 0"/>
			<inertia ixx="1.6027e-06" ixy="0" ixz="0" iyy="8.85355e-06" iyz="0" izz="9.25293e-06"/>
		</inertial>
		<visual>
			<origin xyz="0 0 0" rpy="0 -0 0"/>
			<geometry>
				<mesh filename="stl/HandL_Finger_Ring1_joint_visu.stl" scale="1 1 1"/>
			</geometry>
		</visual>
		<collision>
			<origin xyz="0 0 0" rpy="0 -0 0"/>
			<geometry>
				<mesh filename="stl/HandL_Finger_Ring1_joint_col.stl" scale="1 1 1"/>
			</geometry>
		</collision>
	</link>
        <link name="HandL_Finger_Ring2_link">
		<inertial>
			<mass value="0.05"/>
			<origin xyz="0.013018 -0.00874729 0.00195051" rpy="0 -0 0"/>
			<inertia ixx="2.60839e-06" ixy="0" ixz="0" iyy="1.61897e-05" iyz="0" izz="1.6466e-05"/>
		</inertial>
		<visual>
			<origin xyz="0 0 0" rpy="0 -0 0"/>
			<geometry>
				<mesh filename="stl/HandL_Finger_Ring2_joint_visu.stl" scale="1 1 1"/>
			</geometry>
		</visual>
		<collision>
			<origin xyz="0 0 0" rpy="0 -0 0"/>
			<geometry>
				<mesh filename="stl/HandL_Finger_Ring2_joint_col.stl" scale="1 1 1"/>
			</geometry>
		</collision>
	</link>
        <link name="HandL_Finger_Thumb1_link">
		<inertial>
			<mass value="0.05"/>
			<origin xyz="0.00952735 0.0181103 -0.00222519" rpy="0 -0 0"/>
			<inertia ixx="1.24401e-05" ixy="0" ixz="0" iyy="5.68049e-06" iyz="0" izz="9.92836e-06"/>
		</inertial>
		<visual>
			<origin xyz="0 0 0" rpy="0 -0 0"/>
			<geometry>
				<mesh filename="stl/HandL_Finger_Thumb1_joint_visu.stl" scale="1 1 1"/>
			</geometry>
		</visual>
		<collision>
			<origin xyz="0 0 0" rpy="0 -0 0"/>
			<geometry>
				<mesh filename="stl/HandL_Finger_Thumb1_joint_col.stl" scale="1 1 1"/>
			</geometry>
		</collision>
	</link>
        <link name="HandL_Finger_Thumb2_link">
		<inertial>
			<mass value="0.05"/>
			<origin xyz="0.00960663 0.0191513 0.00442499" rpy="0 -0 0"/>
			<inertia ixx="1.06034e-05" ixy="0" ixz="0" iyy="3.76921e-06" iyz="0" izz="1.14429e-05"/>
		</inertial>
		<visual>
			<origin xyz="0 0 0" rpy="0 -0 0"/>
			<geometry>
				<mesh filename="stl/HandL_Finger_Thumb2_joint_visu.stl" scale="1 1 1"/>
			</geometry>
		</visual>
		<collision>
			<origin xyz="0 0 0" rpy="0 -0 0"/>
			<geometry>
				<mesh filename="stl/HandL_Finger_Thumb2_joint_col.stl" scale="1 1 1"/>
			</geometry>
		</collision>
	</link>
        <link name="HandL_Finger_Thumb3_link">
		<inertial>
			<mass value="0.05"/>
			<origin xyz="0.000359352 0.0189541 0.00230014" rpy="0 -0 0"/>
			<inertia ixx="1.05986e-05" ixy="0" ixz="0" iyy="3.03593e-06" iyz="0" izz="1.09346e-05"/>
		</inertial>
		<visual>
			<origin xyz="0 0 0" rpy="0 -0 0"/>
			<geometry>
				<mesh filename="stl/HandL_Finger_Thumb3_joint_visu.stl" scale="1 1 1"/>
			</geometry>
		</visual>
		<collision>
			<origin xyz="0 0 0" rpy="0 -0 0"/>
			<geometry>
				<mesh filename="stl/HandL_Finger_Thumb3_joint_col.stl" scale="1 1 1"/>
			</geometry>
		</collision>
	</link>
	<link name="HandL_GCP_link">
		<inertial>
			<mass value="0"/>
			<origin xyz="0 0 0" rpy="0 -0 0"/>
			<inertia ixx="1" ixy="0" ixz="0" iyy="1" iyz="0" izz="1"/>
		</inertial>
	</link>
	<link name="HandL_TCP_link">
		<inertial>
			<mass value="0"/>
			<origin xyz="0 0 0" rpy="0 -0 0"/>
			<inertia ixx="1" ixy="0" ixz="0" iyy="1" iyz="0" izz="1"/>
		</inertial>
	</link>
        <link name="HandR_Finger_Index1_link">
		<inertial>
			<mass value="0.05"/>
			<origin xyz="0.0226499 -0.00696484 -1.09538e-05" rpy="0 -0 0"/>
			<inertia ixx="2.07679e-06" ixy="0" ixz="0" iyy="1.09969e-05" iyz="0" izz="1.18508e-05"/>
		</inertial>
		<visual>
			<origin xyz="0 0 0" rpy="0 -0 0"/>
			<geometry>
				<mesh filename="stl/HandR_Finger_Index1_joint_visu.stl" scale="1 1 1"/>
			</geometry>
		</visual>
		<collision>
			<origin xyz="0 0 0" rpy="0 -0 0"/>
			<geometry>
				<mesh filename="stl/HandR_Finger_Index1_joint_col.stl" scale="1 1 1"/>
			</geometry>
		</collision>
	</link>
        <link name="HandR_Finger_Index2_link">
		<inertial>
			<mass value="0.05"/>
			<origin xyz="0.0129353 -0.00674746 -4.63914e-05" rpy="0 -0 0"/>
			<inertia ixx="2.61714e-06" ixy="0" ixz="0" iyy="1.64377e-05" iyz="0" izz="1.67053e-05"/>
		</inertial>
		<visual>
			<origin xyz="0 0 0" rpy="0 -0 0"/>
			<geometry>
				<mesh filename="stl/HandR_Finger_Index2_joint_visu.stl" scale="1 1 1"/>
			</geometry>
		</visual>
		<collision>
			<origin xyz="0 0 0" rpy="0 -0 0"/>
			<geometry>
				<mesh filename="stl/HandR_Finger_Index2_joint_col.stl" scale="1 1 1"/>
			</geometry>
		</collision>
	</link>
        <link name="HandR_Finger_Middle1_link">
		<inertial>
			<mass value="0.05"/>
			<origin xyz="0.0224819 -0.00736877 -0.00016424" rpy="0 -0 0"/>
			<inertia ixx="2.02606e-06" ixy="0" ixz="0" iyy="1.09037e-05" iyz="0" izz="1.17298e-05"/>
		</inertial>
		<visual>
			<origin xyz="0 0 0" rpy="0 -0 0"/>
			<geometry>
				<mesh filename="stl/HandR_Finger_Middle1_joint_visu.stl" scale="1 1 1"/>
			</geometry>
		</visual>
		<collision>
			<origin xyz="0 0 0" rpy="0 -0 0"/>
			<geometry>
				<mesh filename="stl/HandR_Finger_Middle1_joint_col.stl" scale="1 1 1"/>
			</geometry>
		</collision>
	</link>
        <link name="HandR_Finger_Middle2_link">
		<inertial>
			<mass value="0.05"/>
			<origin xyz="0.0128425 -0.00738218 -0.000149725" rpy="0 -0 0"/>
			<inertia ixx="2.7138e-06" ixy="0" ixz="0" iyy="1.60995e-05" iyz="0" izz="1.6484e-05"/>
		</inertial>
		<visual>
			<origin xyz="0 0 0" rpy="0 -0 0"/>
			<geometry>
				<mesh filename="stl/HandR_Finger_Middle2_joint_visu.stl" scale="1 1 1"/>
			</geometry>
		</visual>
		<collision>
			<origin xyz="0 0 0" rpy="0 -0 0"/>
			<geometry>
				<mesh filename="stl/HandR_Finger_Middle2_joint_col.stl" scale="1 1 1"/>
			</geometry>
		</collision>
	</link>
        <link name="HandR_Finger_Ring1_link">
		<inertial>
			<mass value="0.05"/>
			<origin xyz="0.0199805 -0.00550008 -0.0025101" rpy="0 -0 0"/>
			<inertia ixx="1.60289e-06" ixy="0" ixz="0" iyy="8.85386e-06" iyz="0" izz="9.25305e-06"/>
		</inertial>
		<visual>
			<origin xyz="0 0 0" rpy="0 -0 0"/>
			<geometry>
				<mesh filename="stl/HandR_Finger_Ring1_joint_visu.stl" scale="1 1 1"/>
			</geometry>
		</visual>
		<collision>
			<origin xyz="0 0 0" rpy="0 -0 0"/>
			<geometry>
				<mesh filename="stl/HandR_Finger_Ring1_joint_col.stl" scale="1 1 1"/>
			</geometry>
		</collision>
	</link>
        <link name="HandR_Finger_Ring2_link">
		<inertial>
			<mass value="0.05"/>
			<origin xyz="0.0127533 -0.00669734 -0.00250811" rpy="0 -0 0"/>
			<inertia ixx="2.60839e-06" ixy="0" ixz="0" iyy="1.61897e-05" iyz="0" izz="1.64661e-05"/>
		</inertial>
		<visual>
			<origin xyz="0 0 0" rpy="0 -0 0"/>
			<geometry>
				<mesh filename="stl/HandR_Finger_Ring2_joint_visu.stl" scale="1 1 1"/>
			</geometry>
		</visual>
		<collision>
			<origin xyz="0 0 0" rpy="0 -0 0"/>
			<geometry>
				<mesh filename="stl/HandR_Finger_Ring2_joint_col.stl" scale="1 1 1"/>
			</geometry>
		</collision>
	</link>
        <link name="HandR_Finger_Pinky1_link">
		<inertial>
			<mass value="0.05"/>
			<origin xyz="0.0134853 -0.00599024 -0.0025446" rpy="0 -0 0"/>
			<inertia ixx="1.73657e-06" ixy="0" ixz="0" iyy="4.73784e-06" iyz="0" izz="5.27002e-06"/>
		</inertial>
		<visual>
			<origin xyz="0 0 0" rpy="0 -0 0"/>
			<geometry>
                                <mesh filename="stl/HandR_Finger_Pinky1_joint_visu.stl" scale="1 1 1"/>
			</geometry>
		</visual>
		<collision>
			<origin xyz="0 0 0" rpy="0 -0 0"/>
			<geometry>
                                <mesh filename="stl/HandR_Finger_Pinky1_joint_col.stl" scale="1 1 1"/>
			</geometry>
		</collision>
	</link>
        <link name="HandR_Finger_Pinky2_link">
		<inertial>
			<mass value="0.05"/>
			<origin xyz="0.00968729 -0.00686527 -0.00256493" rpy="0 -0 0"/>
			<inertia ixx="2.14949e-06" ixy="0" ixz="0" iyy="1.28698e-05" iyz="0" izz="1.34958e-05"/>
		</inertial>
		<visual>
			<origin xyz="0 0 0" rpy="0 -0 0"/>
			<geometry>
                                <mesh filename="stl/HandR_Finger_Pinky2_joint_visu.stl" scale="1 1 1"/>
			</geometry>
		</visual>
		<collision>
			<origin xyz="0 0 0" rpy="0 -0 0"/>
			<geometry>
                                <mesh filename="stl/HandR_Finger_Pinky2_joint_col.stl" scale="1 1 1"/>
			</geometry>
		</collision>
	</link>
        <link name="HandR_Finger_Thumb1_link">
		<inertial>
			<mass value="0.05"/>
			<origin xyz="0.00747756 0.0201107 0.00219502" rpy="0 -0 0"/>
			<inertia ixx="1.24401e-05" ixy="0" ixz="0" iyy="5.68048e-06" iyz="0" izz="9.92836e-06"/>
		</inertial>
		<visual>
			<origin xyz="0 0 0" rpy="0 -0 0"/>
			<geometry>
				<mesh filename="stl/HandR_Finger_Thumb1_joint_visu.stl" scale="1 1 1"/>
			</geometry>
		</visual>
		<collision>
			<origin xyz="0 0 0" rpy="0 -0 0"/>
			<geometry>
				<mesh filename="stl/HandR_Finger_Thumb1_joint_col.stl" scale="1 1 1"/>
			</geometry>
		</collision>
	</link>
        <link name="HandR_Finger_Thumb2_link">
		<inertial>
			<mass value="0.05"/>
			<origin xyz="0.0095266 0.0211519 -0.00212523" rpy="0 -0 0"/>
			<inertia ixx="1.06034e-05" ixy="0" ixz="0" iyy="3.76921e-06" iyz="0" izz="1.14429e-05"/>
		</inertial>
		<visual>
			<origin xyz="0 0 0" rpy="0 -0 0"/>
			<geometry>
				<mesh filename="stl/HandR_Finger_Thumb2_joint_visu.stl" scale="1 1 1"/>
			</geometry>
		</visual>
		<collision>
			<origin xyz="0 0 0" rpy="0 -0 0"/>
			<geometry>
				<mesh filename="stl/HandR_Finger_Thumb2_joint_col.stl" scale="1 1 1"/>
			</geometry>
		</collision>
	</link>
        <link name="HandR_Finger_Thumb3_link">
		<inertial>
			<mass value="0.05"/>
			<origin xyz="0.00180939 0.0220781 -2.20962e-07" rpy="0 -0 0"/>
			<inertia ixx="1.05987e-05" ixy="0" ixz="0" iyy="3.03593e-06" iyz="0" izz="1.09346e-05"/>
		</inertial>
		<visual>
			<origin xyz="0 0 0" rpy="0 -0 0"/>
			<geometry>
				<mesh filename="stl/HandR_Finger_Thumb3_joint_visu.stl" scale="1 1 1"/>
			</geometry>
		</visual>
		<collision>
			<origin xyz="0 0 0" rpy="0 -0 0"/>
			<geometry>
				<mesh filename="stl/HandR_Finger_Thumb3_joint_col.stl" scale="1 1 1"/>
			</geometry>
		</collision>
	</link>
	<link name="HandR_GCP_link">
		<inertial>
			<mass value="0"/>
			<origin xyz="0 0 0" rpy="0 -0 0"/>
			<inertia ixx="1" ixy="0" ixz="0" iyy="1" iyz="0" izz="1"/>
		</inertial>
	</link>
	<link name="HandR_TCP_link">
		<inertial>
			<mass value="0"/>
			<origin xyz="0 0 0" rpy="0 -0 0"/>
			<inertia ixx="1" ixy="0" ixz="0" iyy="1" iyz="0" izz="1"/>
		</inertial>
	</link>
        <link name="Head_1_link">
		<inertial>
			<mass value="0.07"/>
			<origin xyz="0.0100501 5.62238e-08 -0.000349847" rpy="0 -0 0"/>
			<inertia ixx="2.52845e-05" ixy="0" ixz="0" iyy="3.20675e-05" iyz="0" izz="2.7363e-05"/>
		</inertial>
		<visual>
			<origin xyz="0 0 0" rpy="0 -0 0"/>
			<geometry>
				<mesh filename="stl/Head_1_joint_visu.stl" scale="1 1 1"/>
			</geometry>
		</visual>
		<collision>
			<origin xyz="0 0 0" rpy="0 -0 0"/>
			<geometry>
				<mesh filename="stl/Head_1_joint_col.stl" scale="1 1 1"/>
			</geometry>
		</collision>
	</link>
        <link name="Head_2_link">
		<inertial>
			<mass value="1.34"/>
			<origin xyz="0.00124981 0.0820215 0.0210557" rpy="0 -0 0"/>
			<inertia ixx="0.00954863" ixy="0" ixz="0" iyy="0.00822691" iyz="0" izz="0.00721911"/>
		</inertial>
		<visual>
			<origin xyz="0 0 0" rpy="0 -0 0"/>
			<geometry>
				<mesh filename="stl/Head_2_joint_visu.stl" scale="1 1 1"/>
			</geometry>
		</visual>
		<collision>
			<origin xyz="0 0 0" rpy="0 -0 0"/>
			<geometry>
				<mesh filename="stl/Head_2_joint_col.stl" scale="1 1 1"/>
			</geometry>
		</collision>
	</link>
        <link name="LegL_Ank1_link">
		<inertial>
			<mass value="0.5"/>
			<origin xyz="0 0 -0.000109262" rpy="0 -0 0"/>
			<inertia ixx="3.29711e-05" ixy="0" ixz="0" iyy="3.2789e-05" iyz="0" izz="3.31512e-05"/>
		</inertial>
		<collision>
			<origin xyz="0 0 0" rpy="0 -0 0"/>
			<geometry>
				<mesh filename="stl/sphere10.stl" scale="1 1 1"/>
			</geometry>
		</collision>
	</link>
	<link name="LegL_Ank2_body_link">
		<inertial>
			<mass value="1.94"/>
			<origin xyz="-0.0328382 -0.0160825 0.0358811" rpy="0 -0 0"/>
			<inertia ixx="0.0105498" ixy="0" ixz="0" iyy="0.0103366" iyz="0" izz="0.00444324"/>
		</inertial>
		<visual>
			<origin xyz="0 0 0" rpy="0 -0 0"/>
			<geometry>
				<mesh filename="stl/LegL_Ank2_joint_visu.stl" scale="1 1 1"/>
			</geometry>
		</visual>
		<collision>
			<origin xyz="0 0 0" rpy="0 -0 0"/>
			<geometry>
				<mesh filename="stl/LegL_Ank2_joint_col.stl" scale="1 1 1"/>
			</geometry>
		</collision>
	</link>
        <link name="LegL_Ank2_link">
		<inertial>
			<mass value="0"/>
			<origin xyz="0 0 0" rpy="0 -0 0"/>
			<inertia ixx="1" ixy="0" ixz="0" iyy="1" iyz="0" izz="1"/>
		</inertial>
	</link>
        <link name="LegL_Heel_link">
		<inertial>
			<mass value="0.05"/>
			<origin xyz="-0.000903412 0.00894981 -0.00170385" rpy="0 -0 0"/>
			<inertia ixx="1.59042e-05" ixy="0" ixz="0" iyy="9.82348e-06" iyz="0" izz="7.28604e-06"/>
		</inertial>
		<visual>
			<origin xyz="0 0 0" rpy="0 -0 0"/>
			<geometry>
				<mesh filename="stl/LegL_Heel_joint_visu.stl" scale="1 1 1"/>
			</geometry>
		</visual>
		<collision>
			<origin xyz="0 0 0" rpy="0 -0 0"/>
			<geometry>
				<mesh filename="stl/LegL_Heel_joint_visu.stl" scale="1 1 1"/>
			</geometry>
		</collision>
	</link>
        <link name="LegL_Hip1_link">
		<inertial>
			<mass value="1.33"/>
			<origin xyz="-0.0114784 -0.0190205 0.0463836" rpy="0 -0 0"/>
			<inertia ixx="0.00676843" ixy="0" ixz="0" iyy="0.00676843" iyz="0" izz="0.00453669"/>
		</inertial>
		<visual>
			<origin xyz="0 0 0" rpy="0 -0 0"/>
			<geometry>
				<mesh filename="stl/LegL_Hip1_joint_visu.stl" scale="1 1 1"/>
			</geometry>
		</visual>
		<collision>
			<origin xyz="0 0 0" rpy="0 -0 0"/>
			<geometry>
				<mesh filename="stl/LegL_Hip1_joint_col.stl" scale="1 1 1"/>
			</geometry>
		</collision>
	</link>
        <link name="LegL_Hip2_link">
		<inertial>
			<mass value="0.36"/>
			<origin xyz="0.000313077 0.0280972 0.00778463" rpy="0 -0 0"/>
			<inertia ixx="0.000773543" ixy="0" ixz="0" iyy="0.000379211" iyz="0" izz="0.000858843"/>
		</inertial>
		<visual>
			<origin xyz="0 0 0" rpy="0 -0 0"/>
			<geometry>
				<mesh filename="stl/LegL_Hip2_joint_visu.stl" scale="1 1 1"/>
			</geometry>
		</visual>
		<collision>
			<origin xyz="0 0 0" rpy="0 -0 0"/>
			<geometry>
				<mesh filename="stl/LegL_Hip2_joint_col.stl" scale="1 1 1"/>
			</geometry>
		</collision>
	</link>
        <link name="LegL_Hip3_link">
		<inertial>
			<mass value="5.06"/>
			<origin xyz="-0.149052 -0.134842 0.0788454" rpy="0 -0 0"/>
			<inertia ixx="0.0570551" ixy="0" ixz="0" iyy="0.0867303" iyz="0" izz="0.101375"/>
		</inertial>
		<visual>
			<origin xyz="0 0 0" rpy="0 -0 0"/>
			<geometry>
				<mesh filename="stl/LegL_Hip3_joint_visu.stl" scale="1 1 1"/>
			</geometry>
		</visual>
		<collision>
			<origin xyz="0 0 0" rpy="0 -0 0"/>
			<geometry>
				<mesh filename="stl/LegL_Hip3_joint_col.stl" scale="1 1 1"/>
			</geometry>
		</collision>
	</link>
        <link name="LegL_Knee_link">
		<inertial>
			<mass value="4.25"/>
			<origin xyz="0.0200931 0.0134739 -0.186405" rpy="0 -0 0"/>
			<inertia ixx="0.0898909" ixy="0" ixz="0" iyy="0.0880982" iyz="0" izz="0.0122883"/>
		</inertial>
		<visual>
			<origin xyz="0 0 0" rpy="0 -0 0"/>
			<geometry>
				<mesh filename="stl/LegL_Knee_joint_visu.stl" scale="1 1 1"/>
			</geometry>
		</visual>
		<collision>
			<origin xyz="0 0 0" rpy="0 -0 0"/>
			<geometry>
				<mesh filename="stl/LegL_Knee_joint_col.stl" scale="1 1 1"/>
			</geometry>
		</collision>
	</link>
	<link name="LegL_TCP_link">
		<inertial>
			<mass value="0"/>
			<origin xyz="0 0 0" rpy="0 -0 0"/>
			<inertia ixx="1" ixy="0" ixz="0" iyy="1" iyz="0" izz="1"/>
		</inertial>
	</link>
        <link name="LegL_Toe2_link">
		<inertial>
			<mass value="0.13"/>
			<origin xyz="-0.00255092 -0.0172746 -0.0201781" rpy="0 -0 0"/>
			<inertia ixx="9.91013e-05" ixy="0" ixz="0" iyy="7.72886e-05" iyz="0" izz="2.81054e-05"/>
		</inertial>
		<visual>
			<origin xyz="0 0 0" rpy="0 -0 0"/>
			<geometry>
				<mesh filename="stl/LegL_Toe2_joint_visu.stl" scale="1 1 1"/>
			</geometry>
		</visual>
		<collision>
			<origin xyz="0 0 0" rpy="0 -0 0"/>
			<geometry>
				<mesh filename="stl/LegL_Toe2_joint_visu.stl" scale="1 1 1"/>
			</geometry>
		</collision>
	</link>
        <link name="LegL_Toe_link">
		<inertial>
			<mass value="0.1"/>
			<origin xyz="-0.00248135 -0.0203071 0.00883225" rpy="0 -0 0"/>
			<inertia ixx="4.61473e-05" ixy="0" ixz="0" iyy="2.24261e-05" iyz="0" izz="2.85477e-05"/>
		</inertial>
		<visual>
			<origin xyz="0 0 0" rpy="0 -0 0"/>
			<geometry>
				<mesh filename="stl/LegL_Toe_joint_visu.stl" scale="1 1 1"/>
			</geometry>
		</visual>
		<collision>
			<origin xyz="0 0 0" rpy="0 -0 0"/>
			<geometry>
				<mesh filename="stl/LegL_Toe_joint_visu.stl" scale="1 1 1"/>
			</geometry>
		</collision>
	</link>
        <link name="LegR_Ank1_link">
		<inertial>
			<mass value="0.5"/>
			<origin xyz="0 0 -0.000109262" rpy="0 -0 0"/>
			<inertia ixx="3.29711e-05" ixy="0" ixz="0" iyy="3.2789e-05" iyz="0" izz="3.31512e-05"/>
		</inertial>
		<collision>
			<origin xyz="0 0 0" rpy="0 -0 0"/>
			<geometry>
				<mesh filename="stl/sphere10.stl" scale="1 1 1"/>
			</geometry>
		</collision>
	</link>
	<link name="LegR_Ank2_body_link">
		<inertial>
			<mass value="1.94"/>
			<origin xyz="0.0333756 0.0137197 -0.0381945" rpy="0 -0 0"/>
			<inertia ixx="0.0105497" ixy="0" ixz="0" iyy="0.0103369" iyz="0" izz="0.00444379"/>
		</inertial>
		<visual>
			<origin xyz="0 0 0" rpy="0 -0 0"/>
			<geometry>
				<mesh filename="stl/LegR_Ank2_joint_visu.stl" scale="1 1 1"/>
			</geometry>
		</visual>
		<collision>
			<origin xyz="0 0 0" rpy="0 -0 0"/>
			<geometry>
				<mesh filename="stl/LegR_Ank2_joint_col.stl" scale="1 1 1"/>
			</geometry>
		</collision>
	</link>
        <link name="LegR_Ank2_link">
		<inertial>
			<mass value="0"/>
			<origin xyz="0 0 0" rpy="0 -0 0"/>
			<inertia ixx="1" ixy="0" ixz="0" iyy="1" iyz="0" izz="1"/>
		</inertial>
	</link>
        <link name="LegR_Heel_link">
		<inertial>
			<mass value="0.05"/>
			<origin xyz="0.000999268 0.00152872 0.00901597" rpy="0 -0 0"/>
			<inertia ixx="1.59106e-05" ixy="0" ixz="0" iyy="7.28912e-06" iyz="0" izz="9.82714e-06"/>
		</inertial>
		<visual>
			<origin xyz="0 0 0" rpy="0 -0 0"/>
			<geometry>
				<mesh filename="stl/LegR_Heel_joint_visu.stl" scale="1 1 1"/>
			</geometry>
		</visual>
		<collision>
			<origin xyz="0 0 0" rpy="0 -0 0"/>
			<geometry>
				<mesh filename="stl/LegR_Heel_joint_visu.stl" scale="1 1 1"/>
			</geometry>
		</collision>
	</link>
        <link name="LegR_Hip1_link">
		<inertial>
			<mass value="1.33"/>
			<origin xyz="0.00955501 0.0122137 -0.0512045" rpy="0 -0 0"/>
			<inertia ixx="0.00676843" ixy="0" ixz="0" iyy="0.00676844" iyz="0" izz="0.00453669"/>
		</inertial>
		<visual>
			<origin xyz="0 0 0" rpy="0 -0 0"/>
			<geometry>
				<mesh filename="stl/LegR_Hip1_joint_visu.stl" scale="1 1 1"/>
			</geometry>
		</visual>
		<collision>
			<origin xyz="0 0 0" rpy="0 -0 0"/>
			<geometry>
				<mesh filename="stl/LegR_Hip1_joint_col.stl" scale="1 1 1"/>
			</geometry>
		</collision>
	</link>
        <link name="LegR_Hip2_link">
		<inertial>
			<mass value="0.36"/>
			<origin xyz="-0.00120298 -0.0347459 -0.000660893" rpy="0 -0 0"/>
			<inertia ixx="0.000773544" ixy="0" ixz="0" iyy="0.000379211" iyz="0" izz="0.000858844"/>
		</inertial>
		<visual>
			<origin xyz="0 0 0" rpy="0 -0 0"/>
			<geometry>
				<mesh filename="stl/LegR_Hip2_joint_visu.stl" scale="1 1 1"/>
			</geometry>
		</visual>
		<collision>
			<origin xyz="0 0 0" rpy="0 -0 0"/>
			<geometry>
				<mesh filename="stl/LegR_Hip2_joint_col.stl" scale="1 1 1"/>
			</geometry>
		</collision>
	</link>
        <link name="LegR_Hip3_link">
		<inertial>
			<mass value="5.06"/>
			<origin xyz="0.154728 0.131798 -0.0639989" rpy="0 -0 0"/>
			<inertia ixx="0.0570551" ixy="0" ixz="0" iyy="0.0867304" iyz="0" izz="0.101375"/>
		</inertial>
		<visual>
			<origin xyz="0 0 0" rpy="0 -0 0"/>
			<geometry>
				<mesh filename="stl/LegR_Hip3_joint_visu.stl" scale="1 1 1"/>
			</geometry>
		</visual>
		<collision>
			<origin xyz="0 0 0" rpy="0 -0 0"/>
			<geometry>
				<mesh filename="stl/LegR_Hip3_joint_col.stl" scale="1 1 1"/>
			</geometry>
		</collision>
	</link>
        <link name="LegR_Knee_link">
		<inertial>
			<mass value="4.25"/>
			<origin xyz="-0.0226642 -0.0123348 0.187084" rpy="0 -0 0"/>
			<inertia ixx="0.0898961" ixy="0" ixz="0" iyy="0.0881157" iyz="0" izz="0.0123005"/>
		</inertial>
		<visual>
			<origin xyz="0 0 0" rpy="0 -0 0"/>
			<geometry>
				<mesh filename="stl/LegR_Knee_joint_visu.stl" scale="1 1 1"/>
			</geometry>
		</visual>
		<collision>
			<origin xyz="0 0 0" rpy="0 -0 0"/>
			<geometry>
				<mesh filename="stl/LegR_Knee_joint_col.stl" scale="1 1 1"/>
			</geometry>
		</collision>
	</link>
	<link name="LegR_TCP_link">
		<inertial>
			<mass value="0"/>
			<origin xyz="0 0 0" rpy="0 -0 0"/>
			<inertia ixx="1" ixy="0" ixz="0" iyy="1" iyz="0" izz="1"/>
		</inertial>
	</link>
        <link name="LegR_Toe2_link">
		<inertial>
			<mass value="0.13"/>
			<origin xyz="0.00253024 0.0171326 0.0200666" rpy="0 -0 0"/>
			<inertia ixx="9.90857e-05" ixy="0" ixz="0" iyy="7.72553e-05" iyz="0" izz="2.81231e-05"/>
		</inertial>
		<visual>
			<origin xyz="0 0 0" rpy="0 -0 0"/>
			<geometry>
				<mesh filename="stl/LegR_Toe2_joint_visu.stl" scale="1 1 1"/>
			</geometry>
		</visual>
		<collision>
			<origin xyz="0 0 0" rpy="0 -0 0"/>
			<geometry>
				<mesh filename="stl/LegR_Toe2_joint_visu.stl" scale="1 1 1"/>
			</geometry>
		</collision>
	</link>
        <link name="LegR_Toe_link">
		<inertial>
			<mass value="0.1"/>
			<origin xyz="-0.00249427 -0.008005 0.0202925" rpy="0 -0 0"/>
			<inertia ixx="4.61465e-05" ixy="0" ixz="0" iyy="2.85464e-05" iyz="0" izz="2.24268e-05"/>
		</inertial>
		<visual>
			<origin xyz="0 0 0" rpy="0 -0 0"/>
			<geometry>
				<mesh filename="stl/LegR_Toe_joint_visu.stl" scale="1 1 1"/>
			</geometry>
		</visual>
		<collision>
			<origin xyz="0 0 0" rpy="0 -0 0"/>
			<geometry>
				<mesh filename="stl/LegR_Toe_joint_visu.stl" scale="1 1 1"/>
			</geometry>
		</collision>
	</link>
        <link name="Neck_1_link">
		<inertial>
			<mass value="0.14"/>
			<origin xyz="-2.69888e-08 0.0191001 -0.000249887" rpy="0 -0 0"/>
			<inertia ixx="0.000159421" ixy="0" ixz="0" iyy="9.60035e-05" iyz="0" izz="0.000100439"/>
		</inertial>
		<visual>
			<origin xyz="0 0 0" rpy="0 -0 0"/>
			<geometry>
				<mesh filename="stl/Neck_1_joint_visu.stl" scale="1 1 1"/>
			</geometry>
		</visual>
		<collision>
			<origin xyz="0 0 0" rpy="0 -0 0"/>
			<geometry>
				<mesh filename="stl/Neck_1_joint_col.stl" scale="1 1 1"/>
			</geometry>
		</collision>
	</link>
        <link name="Neck_2_link">
		<inertial>
			<mass value="0.13"/>
			<origin xyz="-1.26894e-07 0.0427501 0.0144084" rpy="0 -0 0"/>
			<inertia ixx="0.000251672" ixy="0" ixz="0" iyy="0.000120919" iyz="0" izz="0.000168382"/>
		</inertial>
		<visual>
			<origin xyz="0 0 0" rpy="0 -0 0"/>
			<geometry>
				<mesh filename="stl/Neck_2_joint_visu.stl" scale="1 1 1"/>
			</geometry>
		</visual>
		<collision>
			<origin xyz="0 0 0" rpy="0 -0 0"/>
			<geometry>
				<mesh filename="stl/Neck_2_joint_col.stl" scale="1 1 1"/>
			</geometry>
		</collision>
	</link>
        <link name="Neck_3_link">
		<inertial>
			<mass value="0.25"/>
			<origin xyz="-0.00675008 -0.0130999 0.0608498" rpy="0 -0 0"/>
			<inertia ixx="0.000465112" ixy="0" ixz="0" iyy="0.000426562" iyz="0" izz="0.00022281"/>
		</inertial>
		<visual>
			<origin xyz="0 0 0" rpy="0 -0 0"/>
			<geometry>
				<mesh filename="stl/Neck_3_joint_visu.stl" scale="1 1 1"/>
			</geometry>
		</visual>
		<collision>
			<origin xyz="0 0 0" rpy="0 -0 0"/>
			<geometry>
				<mesh filename="stl/Neck_3_joint_col.stl" scale="1 1 1"/>
			</geometry>
		</collision>
	</link>
	<link name="Pelvis_link">
		<inertial>
			<mass value="0"/>
			<origin xyz="0 0 0" rpy="0 -0 0"/>
			<inertia ixx="1" ixy="0" ixz="0" iyy="1" iyz="0" izz="1"/>
		</inertial>
	</link>
        <link name="Root_link">
		<inertial>
			<mass value="5"/>
			<origin xyz="-1.41396e-08 -8.38799e-10 -0.0464755" rpy="0 -0 0"/>
			<inertia ixx="1" ixy="0" ixz="0" iyy="1" iyz="0" izz="1"/>
		</inertial>
		<visual>
			<origin xyz="0 0 0" rpy="0 -0 0"/>
			<geometry>
				<mesh filename="stl/Root_joint_visu.stl" scale="1 1 1"/>
			</geometry>
		</visual>
		<collision>
			<origin xyz="0 0 0" rpy="0 -0 0"/>
			<geometry>
				<mesh filename="stl/Root_joint_col.stl" scale="1 1 1"/>
			</geometry>
		</collision>
	</link>
	<link name="TorsoCenter_link">
		<inertial>
			<mass value="0"/>
			<origin xyz="0 0 0" rpy="0 -0 0"/>
			<inertia ixx="1" ixy="0" ixz="0" iyy="1" iyz="0" izz="1"/>
		</inertial>
	</link>
        <link name="Torso_Pitch_link">
		<inertial>
			<mass value="25.49"/>
			<origin xyz="-0.0192648 0.13965 -0.000621773" rpy="0 -0 0"/>
			<inertia ixx="0.50297" ixy="0" ixz="0" iyy="0.332368" iyz="0" izz="0.479884"/>
		</inertial>
		<visual>
			<origin xyz="0 0 0" rpy="0 -0 0"/>
			<geometry>
				<mesh filename="stl/Torso_Pitch_joint_visu.stl" scale="1 1 1"/>
			</geometry>
		</visual>
		<collision>
			<origin xyz="0 0 0" rpy="0 -0 0"/>
			<geometry>
				<mesh filename="stl/Torso_Pitch_joint_col.stl" scale="1 1 1"/>
			</geometry>
		</collision>
	</link>
        <link name="Torso_Yaw_link">
		<inertial>
			<mass value="5.01"/>
			<origin xyz="-0.000749969 -3.16772e-09 0.074585" rpy="0 -0 0"/>
			<inertia ixx="0.0137914" ixy="0" ixz="0" iyy="0.0165096" iyz="0" izz="0.0117209"/>
		</inertial>
		<visual>
			<origin xyz="0 0 0" rpy="0 -0 0"/>
			<geometry>
				<mesh filename="stl/Torso_Yaw_joint_visu.stl" scale="1 1 1"/>
			</geometry>
		</visual>
		<collision>
			<origin xyz="0 0 0" rpy="0 -0 0"/>
			<geometry>
				<mesh filename="stl/Torso_Yaw_joint_col.stl" scale="1 1 1"/>
			</geometry>
		</collision>
	</link>
	<link name="root"/>
        <joint name="ArmL_Elb1_joint" type="revolute">
		<origin xyz="-0.0215 -0.01 -0.1974" rpy="1.57079625 -8.74227979e-08 -1.57079625"/>
		<axis xyz="0 0 1"/>
                <parent link="ArmL_Sho4_link"/>
                <child link="ArmL_Elb1_link"/>
		<limit effort="-1" velocity="-1" lower="-0.0872665" upper="1.81514"/>
	</joint>
        <joint name="ArmL_Elb2_joint" type="revolute">
		<origin xyz="0 -0.0858 -0.0205" rpy="-1.57079637 1.57079625 0"/>
		<axis xyz="0 0 1"/>
                <parent link="ArmL_Elb1_link"/>
                <child link="ArmL_Elb2_link"/>
		<limit effort="-1" velocity="-1" lower="-3.14159" upper="1.5708"/>
	</joint>
        <joint name="ArmL_Sho1_joint" type="revolute">
		<origin xyz="0 0.2103 0" rpy="1.57079625 -8.74227979e-08 8.74227979e-08"/>
		<axis xyz="0 0 1"/>
                <parent link="Torso_Pitch_link"/>
                <child link="ArmL_Sho1_link"/>
		<limit effort="-1" velocity="-1" lower="0" upper="0.785398"/>
	</joint>
        <joint name="ArmL_Sho2_joint" type="revolute">
		<origin xyz="0 0.136249 -0.0599" rpy="1.30899704 -8.74227979e-08 8.74227979e-08"/>
		<axis xyz="0 0 1"/>
                <parent link="ArmL_Sho1_link"/>
                <child link="ArmL_Sho2_link"/>
		<limit effort="-1" velocity="-1" lower="-0.523599" upper="2.61799"/>
	</joint>
        <joint name="ArmL_Sho3_joint" type="revolute">
		<origin xyz="0.0165 0 -0.066" rpy="-1.57079637 1.48352981 1.57079637"/>
		<axis xyz="0 0 1"/>
                <parent link="ArmL_Sho2_link"/>
                <child link="ArmL_Sho3_link"/>
		<limit effort="-1" velocity="-1" lower="-0.261799" upper="1.39626"/>
	</joint>
        <joint name="ArmL_Sho4_joint" type="revolute">
		<origin xyz="0 -0.1026 0.0165" rpy="-1.57079637 -0 0"/>
		<axis xyz="0 0 1"/>
                <parent link="ArmL_Sho3_link"/>
                <child link="ArmL_Sho4_link"/>
		<limit effort="-1" velocity="-1" lower="-1.39626" upper="2.96706"/>
	</joint>
        <joint name="ArmL_Wri1_joint" type="revolute">
		<origin xyz="0 0 -0.1642" rpy="-1.57079625 -8.74227979e-08 1.57079625"/>
		<axis xyz="0 0 1"/>
                <parent link="ArmL_Elb2_link"/>
                <child link="ArmL_Wri1_link"/>
		<limit effort="-1" velocity="-1" lower="-0.349066" upper="0.349066"/>
	</joint>
        <joint name="ArmL_Wri2_joint" type="revolute">
		<origin xyz="0 0 0" rpy="1.57079625 -8.74227979e-08 1.57079625"/>
		<axis xyz="0 0 1"/>
                <parent link="ArmL_Wri1_link"/>
                <child link="ArmL_Wri2_link"/>
		<limit effort="-1" velocity="-1" lower="-1.5708" upper="1.5708"/>
	</joint>
        <joint name="ArmR_Elb1_joint" type="revolute">
		<origin xyz="-0.0215 0.01 0.1974" rpy="-1.57079637 -0 1.57079637"/>
		<axis xyz="0 0 1"/>
                <parent link="ArmR_Sho4_link"/>
                <child link="ArmR_Elb1_link"/>
		<limit effort="-1" velocity="-1" lower="-0.0872665" upper="1.81514"/>
	</joint>
        <joint name="ArmR_Elb2_joint" type="revolute">
		<origin xyz="0 -0.0858 -0.0205" rpy="1.57079637 1.57079625 0"/>
		<axis xyz="0 0 1"/>
                <parent link="ArmR_Elb1_link"/>
                <child link="ArmR_Elb2_link"/>
		<limit effort="-1" velocity="-1" lower="-3.14159" upper="1.5708"/>
	</joint>
        <joint name="ArmR_Sho1_joint" type="revolute">
		<origin xyz="0 0.2103 0" rpy="-1.57079637 -0 0"/>
		<axis xyz="0 0 1"/>
                <parent link="Torso_Pitch_link"/>
                <child link="ArmR_Sho1_link"/>
		<limit effort="-1" velocity="-1" lower="0" upper="0.785398"/>
	</joint>
        <joint name="ArmR_Sho2_joint" type="revolute">
		<origin xyz="0 0.136249 0.0599" rpy="-1.30899704 -8.74227979e-08 8.74227979e-08"/>
		<axis xyz="0 0 1"/>
                <parent link="ArmR_Sho1_link"/>
                <child link="ArmR_Sho2_link"/>
		<limit effort="-1" velocity="-1" lower="-0.523599" upper="2.61799"/>
	</joint>
        <joint name="ArmR_Sho3_joint" type="revolute">
		<origin xyz="-0.0165 0 0.066" rpy="-1.57079637 1.48352981 -1.57079637"/>
		<axis xyz="0 0 1"/>
                <parent link="ArmR_Sho2_link"/>
                <child link="ArmR_Sho3_link"/>
		<limit effort="-1" velocity="-1" lower="-0.261799" upper="1.39626"/>
	</joint>
        <joint name="ArmR_Sho4_joint" type="revolute">
		<origin xyz="0 0.1026 0.0165" rpy="-1.57079637 -0 0"/>
		<axis xyz="0 0 1"/>
                <parent link="ArmR_Sho3_link"/>
                <child link="ArmR_Sho4_link"/>
		<limit effort="-1" velocity="-1" lower="-1.39626" upper="2.96706"/>
	</joint>
        <joint name="ArmR_Wri1_joint" type="revolute">
		<origin xyz="-0.0005 0 0.1642" rpy="1.57079637 -0 -1.57079637"/>
		<axis xyz="0 0 1"/>
                <parent link="ArmR_Elb2_link"/>
                <child link="ArmR_Wri1_link"/>
		<limit effort="-1" velocity="-1" lower="-0.349066" upper="0.349066"/>
	</joint>
        <joint name="ArmR_Wri2_joint" type="revolute">
		<origin xyz="0 0 0" rpy="-1.57079637 -0 1.57079637"/>
		<axis xyz="0 0 1"/>
                <parent link="ArmR_Wri1_link"/>
                <child link="ArmR_Wri2_link"/>
		<limit effort="-1" velocity="-1" lower="-1.5708" upper="1.5708"/>
	</joint>
	<joint name="Chest_joint" type="fixed">
		<origin xyz="0 0 0" rpy="1.57079637 -8.74227766e-08 3.14159274"/>
		<axis xyz="0 0 0"/>
		<parent link="TorsoCenter_link"/>
		<child link="Chest_link"/>
		<limit effort="-1" velocity="-1" lower="0" upper="0"/>
	</joint>
        <joint name="EyeL_1_joint" type="revolute">
		<origin xyz="-0.0105 0.0726517 -0.06315" rpy="1.57079637 -0 -1.57079637"/>
		<axis xyz="0 0 1"/>
                <parent link="Head_2_link"/>
                <child link="EyeL_1_link"/>
		<limit effort="-1" velocity="-1" lower="-0.349066" upper="0.349066"/>
	</joint>
        <joint name="EyeL_2_joint" type="revolute">
		<origin xyz="0 0 0.036" rpy="1.57079637 -0 -1.57079637"/>
		<axis xyz="0 0 1"/>
                <parent link="EyeL_1_link"/>
                <child link="EyeL_2_link"/>
		<limit effort="-1" velocity="-1" lower="-0.698132" upper="0.698132"/>
	</joint>
        <joint name="EyeR_1_joint" type="revolute">
		<origin xyz="0.015 0.0726517 -0.06315" rpy="1.57079637 -0 -1.57079637"/>
		<axis xyz="0 0 1"/>
                <parent link="Head_2_link"/>
                <child link="EyeR_1_link"/>
		<limit effort="-1" velocity="-1" lower="-0.349066" upper="0.349066"/>
	</joint>
        <joint name="EyeR_2_joint" type="revolute">
		<origin xyz="0 0 -0.0315" rpy="-1.57079637 -0 -1.57079637"/>
		<axis xyz="0 0 1"/>
                <parent link="EyeR_1_link"/>
                <child link="EyeR_2_link"/>
		<limit effort="-1" velocity="-1" lower="-0.698132" upper="0.698132"/>
	</joint>
        <joint name="HandL_Finger_Index1_joint" type="revolute">
		<origin xyz="0.08965 0.0096 -0.025" rpy="0 0.087266393 0"/>
		<axis xyz="0 0 1"/>
                <parent link="ArmL_Wri2_link"/>
                <child link="HandL_Finger_Index1_link"/>
		<limit effort="-1" velocity="-1" lower="0" upper="1.5708"/>
	</joint>
        <joint name="HandL_Finger_Index2_joint" type="revolute">
		<origin xyz="0.0453 -0.0002 0" rpy="0 -0 0"/>
		<axis xyz="0 0 1"/>
                <parent link="HandL_Finger_Index1_link"/>
                <child link="HandL_Finger_Index2_link"/>
		<limit effort="-1" velocity="-1" lower="0" upper="1.5708"/>
	</joint>
        <joint name="HandL_Finger_Middle1_joint" type="revolute">
		<origin xyz="0.0913 0.0098 -0.0047" rpy="0 -0 0"/>
		<axis xyz="0 0 1"/>
                <parent link="ArmL_Wri2_link"/>
                <child link="HandL_Finger_Middle1_link"/>
		<limit effort="-1" velocity="-1" lower="0" upper="1.5708"/>
	</joint>
        <joint name="HandL_Finger_Middle2_joint" type="revolute">
		<origin xyz="0.045 -0.00305 0" rpy="0 -0 0"/>
		<axis xyz="0 0 1"/>
                <parent link="HandL_Finger_Middle1_link"/>
                <child link="HandL_Finger_Middle2_link"/>
		<limit effort="-1" velocity="-1" lower="0" upper="1.5708"/>
	</joint>
        <joint name="HandL_Finger_Pinky1_joint" type="revolute">
		<origin xyz="0.08845 0.0097 0.0317" rpy="0 -0.174532697 0"/>
		<axis xyz="0 0 1"/>
                <parent link="ArmL_Wri2_link"/>
                <child link="HandL_Finger_Pinky1_link"/>
		<limit effort="-1" velocity="-1" lower="0" upper="1.5708"/>
	</joint>
        <joint name="HandL_Finger_Pinky2_joint" type="revolute">
		<origin xyz="0.027 0 0" rpy="0 -0 0"/>
		<axis xyz="0 0 1"/>
                <parent link="HandL_Finger_Pinky1_link"/>
                <child link="HandL_Finger_Pinky2_link"/>
		<limit effort="-1" velocity="-1" lower="0" upper="1.5708"/>
	</joint>
        <joint name="HandL_Finger_Ring1_joint" type="revolute">
		<origin xyz="0.0912 0.0098 0.0142" rpy="0 -0.087266393 0"/>
		<axis xyz="0 0 1"/>
                <parent link="ArmL_Wri2_link"/>
                <child link="HandL_Finger_Ring1_link"/>
		<limit effort="-1" velocity="-1" lower="0" upper="1.5708"/>
	</joint>
        <joint name="HandL_Finger_Ring2_joint" type="revolute">
		<origin xyz="0.04 0 0" rpy="0 -0 0"/>
		<axis xyz="0 0 1"/>
                <parent link="HandL_Finger_Ring1_link"/>
                <child link="HandL_Finger_Ring2_link"/>
		<limit effort="-1" velocity="-1" lower="0" upper="1.5708"/>
	</joint>
        <joint name="HandL_Finger_Thumb1_joint" type="revolute">
		<origin xyz="0.0353 0.0098 -0.0111" rpy="-1.57079637 -0 -1.57079637"/>
		<axis xyz="0 0 1"/>
                <parent link="ArmL_Wri2_link"/>
                <child link="HandL_Finger_Thumb1_link"/>
		<limit effort="-1" velocity="-1" lower="0" upper="1.5708"/>
	</joint>
        <joint name="HandL_Finger_Thumb2_joint" type="revolute">
		<origin xyz="0.0035 0.03 0.0043" rpy="0 1.57079625 0"/>
		<axis xyz="0 0 1"/>
                <parent link="HandL_Finger_Thumb1_link"/>
                <child link="HandL_Finger_Thumb2_link"/>
		<limit effort="-1" velocity="-1" lower="0" upper="1.5708"/>
	</joint>
        <joint name="HandL_Finger_Thumb3_joint" type="revolute">
		<origin xyz="0.0029 0.0294 0" rpy="0 -0 0"/>
		<axis xyz="0 0 1"/>
                <parent link="HandL_Finger_Thumb2_link"/>
                <child link="HandL_Finger_Thumb3_link"/>
		<limit effort="-1" velocity="-1" lower="0" upper="1.5708"/>
	</joint>
	<joint name="HandL_GCP_joint" type="fixed">
		<origin xyz="0 0 0.015" rpy="-0.785398185 -0 0"/>
		<axis xyz="0 0 0"/>
		<parent link="HandL_TCP_link"/>
		<child link="HandL_GCP_link"/>
		<limit effort="-1" velocity="-1" lower="0" upper="0"/>
	</joint>
	<joint name="HandL_TCP_joint" type="fixed">
		<origin xyz="0.06 0.02 0" rpy="2.3561945 -1.57079625 2.3561945"/>
		<axis xyz="0 0 0"/>
                <parent link="ArmL_Wri2_link"/>
		<child link="HandL_TCP_link"/>
		<limit effort="-1" velocity="-1" lower="0" upper="0"/>
	</joint>
        <joint name="HandR_Finger_Index1_joint" type="revolute">
		<origin xyz="0.0897 0.0101 0.023" rpy="0 -0.087266393 0"/>
		<axis xyz="0 0 1"/>
                <parent link="ArmR_Wri2_link"/>
                <child link="HandR_Finger_Index1_link"/>
		<limit effort="-1" velocity="-1" lower="0" upper="1.5708"/>
	</joint>
        <joint name="HandR_Finger_Index2_joint" type="revolute">
		<origin xyz="0.04524 0.0002 0" rpy="0 -0 0"/>
		<axis xyz="0 0 1"/>
                <parent link="HandR_Finger_Index1_link"/>
                <child link="HandR_Finger_Index2_link"/>
		<limit effort="-1" velocity="-1" lower="0" upper="1.5708"/>
	</joint>
        <joint name="HandR_Finger_Middle1_joint" type="revolute">
		<origin xyz="0.0912501 0.01025 0.003" rpy="0 -0 0"/>
		<axis xyz="0 0 1"/>
                <parent link="ArmR_Wri2_link"/>
                <child link="HandR_Finger_Middle1_link"/>
		<limit effort="-1" velocity="-1" lower="0" upper="1.5708"/>
	</joint>
        <joint name="HandR_Finger_Middle2_joint" type="revolute">
		<origin xyz="0.045 -0.003 0" rpy="0 -0 0"/>
		<axis xyz="0 0 1"/>
                <parent link="HandR_Finger_Middle1_link"/>
                <child link="HandR_Finger_Middle2_link"/>
		<limit effort="-1" velocity="-1" lower="0" upper="1.5708"/>
	</joint>
        <joint name="HandR_Finger_Ring1_joint" type="revolute">
		<origin xyz="0.091442 0.01025 -0.0138" rpy="0 0.087266393 0"/>
		<axis xyz="0 0 1"/>
                <parent link="ArmR_Wri2_link"/>
                <child link="HandR_Finger_Ring1_link"/>
		<limit effort="-1" velocity="-1" lower="0" upper="1.5708"/>
	</joint>
        <joint name="HandR_Finger_Ring2_joint" type="revolute">
		<origin xyz="0.04 0 0" rpy="0 -0 0"/>
		<axis xyz="0 0 1"/>
                <parent link="HandR_Finger_Ring1_link"/>
                <child link="HandR_Finger_Ring2_link"/>
		<limit effort="-1" velocity="-1" lower="0" upper="1.5708"/>
	</joint>
        <joint name="HandR_Finger_Pinky1_joint" type="revolute">
		<origin xyz="0.0888397 0.01024 -0.0311" rpy="0 0.174532697 0"/>
		<axis xyz="0 0 1"/>
                <parent link="ArmR_Wri2_link"/>
                <child link="HandR_Finger_Pinky1_link"/>
		<limit effort="-1" velocity="-1" lower="0" upper="1.5708"/>
	</joint>
        <joint name="HandR_Finger_Pinky2_joint" type="revolute">
		<origin xyz="0.027 0 0" rpy="0 -0 0"/>
		<axis xyz="0 0 1"/>
                <parent link="HandR_Finger_Pinky1_link"/>
                <child link="HandR_Finger_Pinky2_link"/>
		<limit effort="-1" velocity="-1" lower="0" upper="1.5708"/>
	</joint>
        <joint name="HandR_Finger_Thumb1_joint" type="revolute">
		<origin xyz="0.03527 0.01025 0.0091" rpy="1.57079637 -0 -1.57079637"/>
		<axis xyz="0 0 1"/>
                <parent link="ArmR_Wri2_link"/>
                <child link="HandR_Finger_Thumb1_link"/>
		<limit effort="-1" velocity="-1" lower="0" upper="1.5708"/>
	</joint>
        <joint name="HandR_Finger_Thumb2_joint" type="revolute">
		<origin xyz="0.00375 0.03 -0.00425" rpy="0 -1.57079625 0"/>
		<axis xyz="0 0 1"/>
                <parent link="HandR_Finger_Thumb1_link"/>
                <child link="HandR_Finger_Thumb2_link"/>
		<limit effort="-1" velocity="-1" lower="0" upper="1.5708"/>
	</joint>
        <joint name="HandR_Finger_Thumb3_joint" type="revolute">
		<origin xyz="0.0029 0.0293831 0" rpy="0 -0 0"/>
		<axis xyz="0 0 1"/>
                <parent link="HandR_Finger_Thumb2_link"/>
                <child link="HandR_Finger_Thumb3_link"/>
		<limit effort="-1" velocity="-1" lower="0" upper="1.5708"/>
	</joint>
	<joint name="HandR_GCP_joint" type="fixed">
		<origin xyz="0 0 0.015" rpy="-0.785398185 -0 0"/>
		<axis xyz="0 0 0"/>
		<parent link="HandR_TCP_link"/>
		<child link="HandR_GCP_link"/>
		<limit effort="-1" velocity="-1" lower="0" upper="0"/>
	</joint>
	<joint name="HandR_TCP_joint" type="fixed">
		<origin xyz="0.06 0.02 0" rpy="2.3561945 -1.57079625 2.3561945"/>
		<axis xyz="0 0 0"/>
                <parent link="ArmR_Wri2_link"/>
		<child link="HandR_TCP_link"/>
		<limit effort="-1" velocity="-1" lower="0" upper="0"/>
	</joint>
        <joint name="Head_1_joint" type="revolute">
		<origin xyz="0 0 0.1062" rpy="1.57079637 -0 -3.1415925"/>
		<axis xyz="0 0 1"/>
                <parent link="Neck_3_link"/>
                <child link="Head_1_link"/>
		<limit effort="-1" velocity="-1" lower="-0.174533" upper="0.610865"/>
	</joint>
        <joint name="Head_2_joint" type="revolute">
		<origin xyz="0.00465 0 0" rpy="0 1.57079625 0"/>
		<axis xyz="0 0 1"/>
                <parent link="Head_1_link"/>
                <child link="Head_2_link"/>
		<limit effort="-1" velocity="-1" lower="-0.349066" upper="0.349066"/>
	</joint>
        <joint name="LegL_Ank1_joint" type="revolute">
		<origin xyz="0 0 -0.4085" rpy="0 -1.57079625 0"/>
		<axis xyz="0 0 1"/>
                <parent link="LegL_Knee_link"/>
                <child link="LegL_Ank1_link"/>
		<limit effort="-1" velocity="-1" lower="-0.349066" upper="0.523599"/>
	</joint>
	<joint name="LegL_Ank2_body_joint" type="fixed">
		<origin xyz="0 0 0" rpy="0 -0 0"/>
		<axis xyz="0 0 0"/>
                <parent link="LegL_Ank2_link"/>
		<child link="LegL_Ank2_body_link"/>
		<limit effort="-1" velocity="-1" lower="0" upper="0"/>
	</joint>
        <joint name="LegL_Ank2_joint" type="revolute">
		<origin xyz="0 0 0" rpy="1.57079637 -0 0"/>
		<axis xyz="0 0 1"/>
                <parent link="LegL_Ank1_link"/>
                <child link="LegL_Ank2_link"/>
		<limit effort="-1" velocity="-1" lower="-0.174533" upper="0.174533"/>
	</joint>
        <joint name="LegL_Heel_joint" type="fixed">
		<origin xyz="-0.0795 0 -0.053" rpy="-1.57079637 -0 0"/>
		<axis xyz="0 0 0"/>
                <parent link="LegL_Ank2_link"/>
                <child link="LegL_Heel_link"/>
		<limit effort="-1" velocity="-1" lower="0" upper="0"/>
	</joint>
        <joint name="LegL_Hip1_joint" type="revolute">
		<origin xyz="0.124 0 -0.126" rpy="0 -0.615403175 0"/>
		<axis xyz="0 0 1"/>
                <parent link="Root_link"/>
                <child link="LegL_Hip1_link"/>
		<limit effort="-1" velocity="-1" lower="-0.610865" upper="2.53073"/>
	</joint>
        <joint name="LegL_Hip2_joint" type="revolute">
		<origin xyz="0 0 0" rpy="0.785398185 -1.57079625 0"/>
		<axis xyz="0 0 1"/>
                <parent link="LegL_Hip1_link"/>
                <child link="LegL_Hip2_link"/>
		<limit effort="-1" velocity="-1" lower="0" upper="1.91986"/>
	</joint>
        <joint name="LegL_Hip3_joint" type="revolute">
		<origin xyz="0 0 0" rpy="-1.57079637 -0 0"/>
		<axis xyz="0 0 1"/>
                <parent link="LegL_Hip2_link"/>
                <child link="LegL_Hip3_link"/>
		<limit effort="-1" velocity="-1" lower="-0.523599" upper="1.91986"/>
	</joint>
        <joint name="LegL_Knee_joint" type="revolute">
		<origin xyz="-0.303136 -0.197542 0.173784" rpy="2.09439468 0.615402937 2.3561945"/>
		<axis xyz="1 0 0"/>
                <parent link="LegL_Hip3_link"/>
                <child link="LegL_Knee_link"/>
		<limit effort="-1" velocity="-1" lower="0" upper="1.74533"/>
	</joint>
	<joint name="LegL_TCP_joint" type="fixed">
		<origin xyz="-0.09 0 0" rpy="1.57079637 -0 1.57079637"/>
		<axis xyz="0 0 0"/>
                <parent link="LegL_Ank2_link"/>
		<child link="LegL_TCP_link"/>
		<limit effort="-1" velocity="-1" lower="0" upper="0"/>
	</joint>
        <joint name="LegL_Toe2_joint" type="fixed">
		<origin xyz="-0.0742 -0.0006 0.1311" rpy="-1.13446438 -0 0"/>
		<axis xyz="0 0 0"/>
                <parent link="LegL_Ank2_link"/>
                <child link="LegL_Toe2_link"/>
		<limit effort="-1" velocity="-1" lower="0" upper="0"/>
	</joint>
        <joint name="LegL_Toe_joint" type="fixed">
		<origin xyz="-0.07424 0.0244 0.13112" rpy="-1.57079637 -0 0"/>
		<axis xyz="0 0 0"/>
                <parent link="LegL_Ank2_link"/>
                <child link="LegL_Toe_link"/>
		<limit effort="-1" velocity="-1" lower="0" upper="0"/>
	</joint>
        <joint name="LegR_Ank1_joint" type="revolute">
		<origin xyz="0 0 0.4085" rpy="0 -1.57079625 0"/>
		<axis xyz="0 0 1"/>
                <parent link="LegR_Knee_link"/>
                <child link="LegR_Ank1_link"/>
		<limit effort="-1" velocity="-1" lower="-0.349066" upper="0.523599"/>
	</joint>
	<joint name="LegR_Ank2_body_joint" type="fixed">
		<origin xyz="0 0 0" rpy="0 -0 0"/>
		<axis xyz="0 0 0"/>
                <parent link="LegR_Ank2_link"/>
		<child link="LegR_Ank2_body_link"/>
		<limit effort="-1" velocity="-1" lower="0" upper="0"/>
	</joint>
        <joint name="LegR_Ank2_joint" type="revolute">
		<origin xyz="0 0 0" rpy="1.57079637 -0 0"/>
		<axis xyz="0 0 1"/>
                <parent link="LegR_Ank1_link"/>
                <child link="LegR_Ank2_link"/>
		<limit effort="-1" velocity="-1" lower="-0.174533" upper="0.174533"/>
	</joint>
        <joint name="LegR_Heel_joint" type="fixed">
		<origin xyz="0.07945 0 0.0529" rpy="0 -0 0"/>
		<axis xyz="0 0 0"/>
                <parent link="LegR_Ank2_link"/>
                <child link="LegR_Heel_link"/>
		<limit effort="-1" velocity="-1" lower="0" upper="0"/>
	</joint>
        <joint name="LegR_Hip1_joint" type="revolute">
		<origin xyz="-0.124 0 -0.126" rpy="-3.1415925 0.615403175 0"/>
		<axis xyz="0 0 1"/>
                <parent link="Root_link"/>
                <child link="LegR_Hip1_link"/>
		<limit effort="-1" velocity="-1" lower="-0.610865" upper="2.53073"/>
	</joint>
        <joint name="LegR_Hip2_joint" type="revolute">
		<origin xyz="0 0 0" rpy="0.785398185 -1.57079625 0"/>
		<axis xyz="0 0 1"/>
                <parent link="LegR_Hip1_link"/>
                <child link="LegR_Hip2_link"/>
		<limit effort="-1" velocity="-1" lower="0" upper="1.91986"/>
	</joint>
        <joint name="LegR_Hip3_joint" type="revolute">
		<origin xyz="0 0 0" rpy="-1.57079637 -0 0"/>
		<axis xyz="0 0 1"/>
                <parent link="LegR_Hip2_link"/>
                <child link="LegR_Hip3_link"/>
		<limit effort="-1" velocity="-1" lower="-0.523599" upper="1.91986"/>
	</joint>
        <joint name="LegR_Knee_joint" type="revolute">
		<origin xyz="0.3031 0.1975 -0.1738" rpy="2.09439468 0.615402937 2.3561945"/>
		<axis xyz="1 0 0"/>
                <parent link="LegR_Hip3_link"/>
                <child link="LegR_Knee_link"/>
		<limit effort="-1" velocity="-1" lower="0" upper="1.74533"/>
	</joint>
	<joint name="LegR_TCP_joint" type="fixed">
		<origin xyz="0.09 0 0" rpy="-1.57079637 4.37113883e-08 1.57079637"/>
		<axis xyz="0 0 0"/>
                <parent link="LegR_Ank2_link"/>
		<child link="LegR_TCP_link"/>
		<limit effort="-1" velocity="-1" lower="0" upper="0"/>
	</joint>
        <joint name="LegR_Toe2_joint" type="fixed">
		<origin xyz="0.0743 0.0006 -0.1312" rpy="-1.13446438 -0 0"/>
		<axis xyz="0 0 0"/>
                <parent link="LegR_Ank2_link"/>
                <child link="LegR_Toe2_link"/>
		<limit effort="-1" velocity="-1" lower="0" upper="0"/>
	</joint>
        <joint name="LegR_Toe_joint" type="fixed">
		<origin xyz="0.0743 -0.0254 -0.13117" rpy="3.14159274 -1.50996001e-07 3.14159274"/>
		<axis xyz="0 0 0"/>
                <parent link="LegR_Ank2_link"/>
                <child link="LegR_Toe_link"/>
		<limit effort="-1" velocity="-1" lower="0" upper="0"/>
	</joint>
        <joint name="Neck_1_joint" type="revolute">
		<origin xyz="0 0.3073 0" rpy="0 -0 -1.57079637"/>
		<axis xyz="0 0 1"/>
                <parent link="Torso_Pitch_link"/>
                <child link="Neck_1_link"/>
		<limit effort="-1" velocity="-1" lower="-0.785398" upper="0.610865"/>
	</joint>
        <joint name="Neck_2_joint" type="revolute">
		<origin xyz="0 0 0" rpy="-1.57079637 1.57079625 0"/>
		<axis xyz="0 0 1"/>
                <parent link="Neck_1_link"/>
                <child link="Neck_2_link"/>
		<limit effort="-1" velocity="-1" lower="-1.22173" upper="1.22173"/>
	</joint>
        <joint name="Neck_3_joint" type="revolute">
		<origin xyz="0 0.0338 0" rpy="-1.57079637 1.57079625 0"/>
		<axis xyz="0 0 1"/>
                <parent link="Neck_2_link"/>
                <child link="Neck_3_link"/>
		<limit effort="-1" velocity="-1" lower="-1.5708" upper="1.5708"/>
	</joint>
	<joint name="Pelvis_joint" type="fixed">
		<origin xyz="0 0 0" rpy="0 -0 0"/>
		<axis xyz="0 0 0"/>
                <parent link="Root_link"/>
		<child link="Pelvis_link"/>
		<limit effort="-1" velocity="-1" lower="0" upper="0"/>
	</joint>
        <joint name="Root_joint" type="fixed">
		<origin xyz="0 0 0" rpy="0 -0 0"/>
		<axis xyz="0 0 0"/>
		<parent link="root"/>
                <child link="Root_link"/>
		<limit effort="-1" velocity="-1" lower="0" upper="0"/>
	</joint>
	<joint name="TorsoCenter_joint" type="fixed">
		<origin xyz="0 0 0" rpy="0 -0 0"/>
		<axis xyz="0 0 0"/>
                <parent link="Torso_Pitch_link"/>
		<child link="TorsoCenter_link"/>
		<limit effort="-1" velocity="-1" lower="0" upper="0"/>
	</joint>
        <joint name="Torso_Pitch_joint" type="revolute">
		<origin xyz="0 0 0.099879" rpy="1.57079637 -0 1.57079637"/>
		<axis xyz="0 0 1"/>
                <parent link="Torso_Yaw_link"/>
                <child link="Torso_Pitch_link"/>
		<limit effort="-1" velocity="-1" lower="-0.785398" upper="0.785398"/>
	</joint>
        <joint name="Torso_Yaw_joint" type="revolute">
		<origin xyz="0 0 0" rpy="0 -0 0"/>
		<axis xyz="0 0 1"/>
                <parent link="Root_link"/>
                <child link="Torso_Yaw_link"/>
		<limit effort="-1" velocity="-1" lower="-1.5708" upper="1.5708"/>
	</joint>
</robot>
